Watching for file changes with StatReloader
"POST /student/studentlogin HTTP/1.1" 302 0
"GET /afterlogin HTTP/1.1" 302 0
"GET /student/student-dashboard HTTP/1.1" 200 7304
"GET /static/image/student.png HTTP/1.1" 200 5814
Not Found: /student/background.png
"GET /student/background.png HTTP/1.1" 404 8657
"GET / HTTP/1.1" 200 3713
C:\Users\Kaxa\Videos\onlinexamination\exam\views.py changed, reloading.
Watching for file changes with StatReloader
"GET /student/student-exam HTTP/1.1" 200 6174
Not Found: /student/background.png
"GET /student/background.png HTTP/1.1" 404 8657
"GET /teacher/teacherclick HTTP/1.1" 200 3812
"GET /student/take-exam/1 HTTP/1.1" 200 6951
Not Found: /student/take-exam/background.png
"GET /student/take-exam/background.png HTTP/1.1" 404 8687
"GET /student/studentclick HTTP/1.1" 200 3823
"GET /student/start-exam/1 HTTP/1.1" 200 8800
Not Found: /student/start-exam/background.png
"GET /student/start-exam/background.png HTTP/1.1" 404 8690
"POST /student/calculate-marks HTTP/1.1" 302 0
"GET /student/view-result HTTP/1.1" 200 6174
Not Found: /student/background.png
"GET /student/background.png HTTP/1.1" 404 8657
"GET /student/check-marks/1 HTTP/1.1" 200 6079
Not Found: /student/check-marks/background.png
"GET /student/check-marks/background.png HTTP/1.1" 404 8693
C:\Users\Kaxa\Videos\onlinexamination\exam\views.py changed, reloading.
Watching for file changes with StatReloader
"GET /student/studentsignup HTTP/1.1" 200 5425
"GET /student/studentsignup HTTP/1.1" 200 5425
"GET /student/studentsignup HTTP/1.1" 200 5425
Internal Server Error: /student/studentsignup
Traceback (most recent call last):
  File "C:\Users\Kaxa\Videos\onlinexamination\venv\lib\site-packages\django\db\backends\utils.py", line 86, in _execute
    return self.cursor.execute(sql, params)
  File "C:\Users\Kaxa\Videos\onlinexamination\venv\lib\site-packages\django\db\backends\sqlite3\base.py", line 396, in execute
    return Database.Cursor.execute(self, query, params)
sqlite3.IntegrityError: UNIQUE constraint failed: auth_user.username

The above exception was the direct cause of the following exception:

Traceback (most recent call last):
  File "C:\Users\Kaxa\Videos\onlinexamination\venv\lib\site-packages\django\core\handlers\exception.py", line 34, in inner
    response = get_response(request)
  File "C:\Users\Kaxa\Videos\onlinexamination\venv\lib\site-packages\django\core\handlers\base.py", line 115, in _get_response
    response = self.process_exception_by_middleware(e, request)
  File "C:\Users\Kaxa\Videos\onlinexamination\venv\lib\site-packages\django\core\handlers\base.py", line 113, in _get_response
    response = wrapped_callback(request, *callback_args, **callback_kwargs)
  File "C:\Users\Kaxa\Videos\onlinexamination\student\views.py", line 27, in student_signup_view
    user=userForm.save()
  File "C:\Users\Kaxa\Videos\onlinexamination\venv\lib\site-packages\django\forms\models.py", line 459, in save
    self.instance.save()
  File "C:\Users\Kaxa\Videos\onlinexamination\venv\lib\site-packages\django\contrib\auth\base_user.py", line 66, in save
    super().save(*args, **kwargs)
  File "C:\Users\Kaxa\Videos\onlinexamination\venv\lib\site-packages\django\db\models\base.py", line 745, in save
    self.save_base(using=using, force_insert=force_insert,
  File "C:\Users\Kaxa\Videos\onlinexamination\venv\lib\site-packages\django\db\models\base.py", line 782, in save_base
    updated = self._save_table(
  File "C:\Users\Kaxa\Videos\onlinexamination\venv\lib\site-packages\django\db\models\base.py", line 887, in _save_table
    results = self._do_insert(cls._base_manager, using, fields, returning_fields, raw)
  File "C:\Users\Kaxa\Videos\onlinexamination\venv\lib\site-packages\django\db\models\base.py", line 924, in _do_insert
    return manager._insert(
  File "C:\Users\Kaxa\Videos\onlinexamination\venv\lib\site-packages\django\db\models\manager.py", line 82, in manager_method
    return getattr(self.get_queryset(), name)(*args, **kwargs)
  File "C:\Users\Kaxa\Videos\onlinexamination\venv\lib\site-packages\django\db\models\query.py", line 1204, in _insert
    return query.get_compiler(using=using).execute_sql(returning_fields)
  File "C:\Users\Kaxa\Videos\onlinexamination\venv\lib\site-packages\django\db\models\sql\compiler.py", line 1391, in execute_sql
    cursor.execute(sql, params)
  File "C:\Users\Kaxa\Videos\onlinexamination\venv\lib\site-packages\django\db\backends\utils.py", line 100, in execute
    return super().execute(sql, params)
  File "C:\Users\Kaxa\Videos\onlinexamination\venv\lib\site-packages\django\db\backends\utils.py", line 68, in execute
    return self._execute_with_wrappers(sql, params, many=False, executor=self._execute)
  File "C:\Users\Kaxa\Videos\onlinexamination\venv\lib\site-packages\django\db\backends\utils.py", line 77, in _execute_with_wrappers
    return executor(sql, params, many, context)
  File "C:\Users\Kaxa\Videos\onlinexamination\venv\lib\site-packages\django\db\backends\utils.py", line 86, in _execute
    return self.cursor.execute(sql, params)
  File "C:\Users\Kaxa\Videos\onlinexamination\venv\lib\site-packages\django\db\utils.py", line 90, in __exit__
    raise dj_exc_value.with_traceback(traceback) from exc_value
  File "C:\Users\Kaxa\Videos\onlinexamination\venv\lib\site-packages\django\db\backends\utils.py", line 86, in _execute
    return self.cursor.execute(sql, params)
  File "C:\Users\Kaxa\Videos\onlinexamination\venv\lib\site-packages\django\db\backends\sqlite3\base.py", line 396, in execute
    return Database.Cursor.execute(self, query, params)
django.db.utils.IntegrityError: UNIQUE constraint failed: auth_user.username
"GET /student/studentsignup HTTP/1.1" 200 5425
C:\Users\Kaxa\Videos\onlinexamination\exam\views.py changed, reloading.
